Workbook
Name ADI: #REF!
Name District: #REF!
Name segment_lookup: #REF!

Sheet Historic Data (Region)
B1: Sales (T3 Timeframes) | L1: Sales (T1 Timeframes) | V1: T1 Site Visits | AF1: VLPs | AP1: VLPs | In-Market Only | AZ1: T3 SV + VDPs | BC1: T3 Sales Visits | BM1: T3 VDPs | BW1: 2026 T1 HVAs |Total | CH1: 2026 HVAs |T1 to T3 Referrals | CS1: 2026 HVAs |T1 VDP Visits | DD1: 2026 MVAs | (total 5x actions) | DO1: 2026 MVAs | (In-Market Only) | DY1: Leads | EI1: Endemic VDPs | ES1: Total Shop Actions | Total = T3 Referrals + T1 VDPs + Sales Visits | Models = T3 Referrals + T1 VDPs + T3 VDPs | FC1: Total Research Actions | T1 MVAs + Endemic VDPs
C2: Mountain Region | D2: Mid Atlantic Region | E2: South Region | F2: Central Region | G2: West Region | H2: South Central Region | I2: East Region | J2: Total | M2: Mountain Region | N2: Mid Atlantic Region | O2: South Region | P2: Central Region | Q2: West Region | R2: South Central Region | S2: East Region | T2: Total | W2: Mountain Region | X2: Mid Atlantic Region | Y2: South Region | Z2: Central Region | AA2: West Region | AB2: South Central Region | AC2: East Region | AD2: Total | AG2: Mountain Region | AH2: Mid Atlantic Region | AI2: South Region | AJ2: Central Region | AK2: West Region | AL2: South Central Region | AM2: East Region | AN2: Total | AQ2: Mountain Region | AR2: Mid Atlantic Region | AS2: South Region | AT2: Central Region | AU2: West Region | AV2: South Central Region | AW2: East Region | AX2: Total | BA2: Total | BC2: Mountain Region | BD2: Mid Atlantic Region | BE2: South Region | BF2: Central Region | BG2: West Region | BH2: South Central Region | BI2: East Region | BJ2: Sum of Regions | BK2: National | BM2: Mountain Region | BN2: Mid Atlantic Region | BO2: South Region | BP2: Central Region | BQ2: West Region | BR2: South Central Region | BS2: East Region | BT2: Sum of Regions | BU2: National | BX2: Mountain Region | BY2: Mid Atlantic Region | BZ2: South Region | CA2: Central Region | CB2: West Region | CC2: South Central Region | CD2: East Region | CE2: Sum of Regions | CF2: National | CI2: Mountain Region | CJ2: Mid Atlantic Region | CK2: South Region | CL2: Central Region | CM2: West Region | CN2: South Central Region | CO2: East Region | CP2: Sum of Regions | CQ2: National | CT2: Mountain Region | CU2: Mid Atlantic Region | CV2: South Region | CW2: Central Region | CX2: West Region | CY2: South Central Region | CZ2: East Region | DA2: Sum of Regions | DB2: National | DE2: Mountain Region | DF2: Mid Atlantic Region | DG2: South Region | DH2: Central Region | DI2: West Region | DJ2: South Central Region | DK2: East Region | DL2: Sum of Regions | DM2: National | DP2: Mountain Region | DQ2: Mid Atlantic Region | DR2: South Region | DS2: Central Region | DT2: West Region | DU2: South Central Region | DV2: East Region | DW2: Total | DZ2: Mountain Region | EA2: Mid Atlantic Region | EB2: South Region | EC2: Central Region | ED2: West Region | EE2: South Central Region | EF2: East Region | EG2: Total | EJ2: Mountain Region | EK2: Mid Atlantic Region | EL2: South Region | EM2: Central Region | EN2: West Region | EO2: South Central Region | EP2: East Region | EQ2: Total | ET2: Mountain Region | EU2: Mid Atlantic Region | EV2: South Region | EW2: Central Region | EX2: West Region | EY2: South Central Region | EZ2: East Region | FA2: Total | FD2: Mountain Region | FE2: Mid Atlantic Region | FF2: South Region | FG2: Central Region | FH2: West Region | FI2: South Central Region | FJ2: East Region | FK2: Total
B3: Jan - Dec '25 | C3: =SUM(C50:C61) -> 4330 | D3: =SUM(D50:D61) -> 6539 | E3: =SUM(E50:E61) -> 18728 | F3: =SUM(F50:F61) -> 9217 | G3: =SUM(G50:G61) -> 11336 | H3: =SUM(H50:H61) -> 9177 | I3: =SUM(I50:I61) -> 14171 | J3: =SUM(J50:J61) -> 74084 | L3: Jan - Dec '25 | M3: =SUM(M50:M61) -> 4330 | N3: =SUM(N50:N61) -> 6539 | O3: =SUM(O50:O61) -> 18728 | P3: =SUM(P50:P61) -> 9217 | Q3: =SUM(Q50:Q61) -> 11336 | R3: =SUM(R50:R61) -> 9177 | S3: =SUM(S50:S61) -> 14171 | T3: =SUM(T50:T61) -> 74084 | V3: Jan - Dec '25 | W3: =SUM(W50:W61) -> 2035880 | X3: =SUM(X50:X61) -> 3351262 | Y3: =SUM(Y50:Y61) -> 6304361 | Z3: =SUM(Z50:Z61) -> 6052241 | AA3: =SUM(AA50:AA61) -> 5503121 | AB3: =SUM(AB50:AB61) -> 5109111 | AC3: =SUM(AC50:AC61) -> 7209596 | AD3: =SUM(AD50:AD61) -> 36706663 | AF3: Jan - Dec '25 | AG3: =SUM(AG50:AG61) -> 1592067 | AH3: =SUM(AH50:AH61) -> 2550908 | AI3: =SUM(AI50:AI61) -> 4849250 | AJ3: =SUM(AJ50:AJ61) -> 4598493 | AK3: =SUM(AK50:AK61) -> 4347201 | AL3: =SUM(AL50:AL61) -> 3969124 | AM3: =SUM(AM50:AM61) -> 5568814 | AN3: =SUM(AN50:AN61) -> 28207432 | AP3: Jan - Dec '25 | AQ3: =SUM(AQ50:AQ61) -> 0 | AR3: =SUM(AR50:AR61) -> 0 | AS3: =SUM(AS50:AS61) -> 0 | AT3: =SUM(AT50:AT61) -> 0 | AU3: =SUM(AU50:AU61) -> 0 | AV3: =SUM(AV50:AV61) -> 0 | AW3: =SUM(AW50:AW61) -> 0 | AX3: =SUM(AX50:AX61) -> 0 | AZ3: Jan - Dec '25 | BA3: =SUM(BA50:BA61) -> 2165412 | BC3: =SUM(BC50:BC61) -> 1382533 | BD3: =SUM(BD50:BD61) -> 2100926 | BE3: =SUM(BE50:BE61) -> 5302232 | BF3: =SUM(BF50:BF61) -> 2574418 | BG3: =SUM(BG50:BG61) -> 2473390 | BH3: =SUM(BH50:BH61) -> 3576439 | BI3: =SUM(BI50:BI61) -> 3338475 | BJ3: =SUM(BJ50:BJ61) -> 20748413 | BK3: =SUM(BK50:BK61) -> 20758263 | BM3: =SUM(BM50:BM61) -> 782879 | BN3: =SUM(BN50:BN61) -> 1502872 | BO3: =SUM(BO50:BO61) -> 3410524 | BP3: =SUM(BP50:BP61) -> 1670443 | BQ3: =SUM(BQ50:BQ61) -> 1621384 | BR3: =SUM(BR50:BR61) -> 1960699 | BS3: =SUM(BS50:BS61) -> 2225417 | BT3: =SUM(BT50:BT61) -> 13174218 | BU3: =SUM(BU50:BU61) -> 13177283 | BW3: Jan - Dec '25 | BX3: =SUM(BX50:BX61) -> 89194 | BY3: =SUM(BY50:BY61) -> 182613 | BZ3: =SUM(BZ50:BZ61) -> 339902 | CA3: =SUM(CA50:CA61) -> 320129 | CB3: =SUM(CB50:CB61) -> 238169 | CC3: =SUM(CC50:CC61) -> 249571 | CD3: =SUM(CD50:CD61) -> 394247 | CE3: =SUM(CE50:CE61) -> 1813825 | CF3: =SUM(CF50:CF61) -> 1728761 | CH3: Jan - Dec '25 | CI3: =SUM(CI50:CI61) -> 42281 | CJ3: =SUM(CJ50:CJ61) -> 92549 | CK3: =SUM(CK50:CK61) -> 170076 | CL3: =SUM(CL50:CL61) -> 161651 | CM3: =SUM(CM50:CM61) -> 113588 | CN3: =SUM(CN50:CN61) -> 121094 | CO3: =SUM(CO50:CO61) -> 197822 | CP3: =SUM(CP50:CP61) -> 899061 | CQ3: =SUM(CQ50:CQ61) -> 768740 | CS3: Jan - Dec '25 | CT3: =SUM(CT50:CT61) -> 46913 | CU3: =SUM(CU50:CU61) -> 90064 | CV3: =SUM(CV50:CV61) -> 169826 | CW3: =SUM(CW50:CW61) -> 158478 | CX3: =SUM(CX50:CX61) -> 124581 | CY3: =SUM(CY50:CY61) -> 128477 | CZ3: =SUM(CZ50:CZ61) -> 196425 | DA3: =SUM(DA50:DA61) -> 914764 | DB3: =SUM(DB50:DB61) -> 960021 | DD3: Jan - Dec '25 | DE3: =SUM(DE50:DE61) -> 359856 | DF3: =SUM(DF50:DF61) -> 584457 | DG3: =SUM(DG50:DG61) -> 1103246 | DH3: =SUM(DH50:DH61) -> 1032905 | DI3: =SUM(DI50:DI61) -> 879558 | DJ3: =SUM(DJ50:DJ61) -> 844887 | DK3: =SUM(DK50:DK61) -> 1410224 | DL3: =SUM(DL50:DL61) -> 6215133 | DM3: =SUM(DM50:DM61) -> 6374314 | DO3: Jan - Dec '25 | DP3: =SUM(DP50:DP61) -> 0 | DQ3: =SUM(DQ50:DQ61) -> 0 | DR3: =SUM(DR50:DR61) -> 0 | DS3: =SUM(DS50:DS61) -> 0 | DT3: =SUM(DT50:DT61) -> 0 | DU3: =SUM(DU50:DU61) -> 0 | DV3: =SUM(DV50:DV61) -> 0 | DW3: =SUM(DW50:DW61) -> 0 | DY3: Jan - Dec '25 | DZ3: =SUM(DZ50:DZ61) -> 0 | EA3: =SUM(EA50:EA61) -> 0 | EB3: =SUM(EB50:EB61) -> 0 | EC3: =SUM(EC50:EC61) -> 0 | ED3: =SUM(ED50:ED61) -> 0 | EE3: =SUM(EE50:EE61) -> 0 | EF3: =SUM(EF50:EF61) -> 0 | EG3: =SUM(EG50:EG61) -> 0 | EI3: Jan - Dec '25 | EJ3: =SUM(EJ50:EJ61) -> 0 | EK3: =SUM(EK50:EK61) -> 0 | EL3: =SUM(EL50:EL61) -> 0 | EM3: =SUM(EM50:EM61) -> 0 | EN3: =SUM(EN50:EN61) -> 0 | EO3: =SUM(EO50:EO61) -> 0 | EP3: =SUM(EP50:EP61) -> 0 | EQ3: =SUM(EQ50:EQ61) -> 0 | ES3: Jan - Dec '25 | ET3: =SUM(ET50:ET61) -> 0 | EU3: =SUM(EU50:EU61) -> 0 | EV3: =SUM(EV50:EV61) -> 0 | EW3: =SUM(EW50:EW61) -> 0 | EX3: =SUM(EX50:EX61) -> 0 | EY3: =SUM(EY50:EY61) -> 0 | EZ3: =SUM(EZ50:EZ61) -> 0 | FA3: =SUM(FA50:FA61) -> 0 | FC3: Jan - Dec '25 | FD3: =SUM(FD50:FD61) -> 0 | FE3: =SUM(FE50:FE61) -> 0 | FF3: =SUM(FF50:FF61) -> 0 | FG3: =SUM(FG50:FG61) -> 0 | FH3: =SUM(FH50:FH61) -> 0 | FI3: =SUM(FI50:FI61) -> 0 | FJ3: =SUM(FJ50:FJ61) -> 0 | FK3: =SUM(FK50:FK61) -> 0
B4: 25 Sig Even Months | C4: =SUM(C52,C56,C57,C60:C61) -> 1954 | D4: =SUM(D52,D56,D57,D60:D61) -> 3078 | E4: =SUM(E52,E56,E57,E60:E61) -> 8917 | F4: =SUM(F52,F56,F57,F60:F61) -> 4222 | G4: =SUM(G52,G56,G57,G60:G61) -> 5422 | H4: =SUM(H52,H56,H57,H60:H61) -> 4368 | I4: =SUM(I52,I56,I57,I60:I61) -> 6790 | J4: =SUM(J52,J56,J57,J60:J61) -> 34917 | L4: 25 Sig Even Months | M4: =SUM(M52,M57,M60:M61) -> 1623 | N4: =SUM(N52,N57,N60:N61) -> 2493 | O4: =SUM(O52,O57,O60:O61) -> 7412 | P4: =SUM(P52,P57,P60:P61) -> 3412 | Q4: =SUM(Q52,Q57,Q60:Q61) -> 4488 | R4: =SUM(R52,R57,R60:R61) -> 3674 | S4: =SUM(S52,S57,S60:S61) -> 5585 | T4: =SUM(T52,T57,T60:T61) -> 28817 | V4: 25 Sig Even Months | W4: =SUM(W52,W57,W60:W61) -> 743117 | X4: =SUM(X52,X57,X60:X61) -> 1195036 | Y4: =SUM(Y52,Y57,Y60:Y61) -> 2294121 | Z4: =SUM(Z52,Z57,Z60:Z61) -> 2117717 | AA4: =SUM(AA52,AA57,AA60:AA61) -> 2034315 | AB4: =SUM(AB52,AB57,AB60:AB61) -> 1832174 | AC4: =SUM(AC52,AC57,AC60:AC61) -> 2537458 | AD4: =SUM(AD52,AD57,AD60:AD61) -> 13126705 | AF4: 25 Sig Even Months | AG4: =SUM(AG52,AG57,AG60:AG61) -> 591201 | AH4: =SUM(AH52,AH57,AH60:AH61) -> 931638 | AI4: =SUM(AI52,AI57,AI60:AI61) -> 1808606 | AJ4: =SUM(AJ52,AJ57,AJ60:AJ61) -> 1648861 | AK4: =SUM(AK52,AK57,AK60:AK61) -> 1618605 | AL4: =SUM(AL52,AL57,AL60:AL61) -> 1470063 | AM4: =SUM(AM52,AM57,AM60:AM61) -> 1991434 | AN4: =SUM(AN52,AN57,AN60:AN61) -> 10291299 | AP4: 25 Sig Even Months | AQ4: =SUM(AQ52,AQ57,AQ60:AQ61) -> 0 | AR4: =SUM(AR52,AR57,AR60:AR61) -> 0 | AS4: =SUM(AS52,AS57,AS60:AS61) -> 0 | AT4: =SUM(AT52,AT57,AT60:AT61) -> 0 | AU4: =SUM(AU52,AU57,AU60:AU61) -> 0 | AV4: =SUM(AV52,AV57,AV60:AV61) -> 0 | AW4: =SUM(AW52,AW57,AW60:AW61) -> 0 | AX4: =SUM(AX52,AX57,AX60:AX61) -> 0 | AZ4: 25 Sig Even Months | BA4: =SUM(BA52,BA56,BA57,BA60:BA61) -> 946497 | BC4: =SUM(BC52,BC56,BC57,BC60:BC61) -> 607242 | BD4: =SUM(BD52,BD56,BD57,BD60:BD61) -> 920836 | BE4: =SUM(BE52,BE56,BE57,BE60:BE61) -> 2361144 | BF4: =SUM(BF52,BF56,BF57,BF60:BF61) -> 1109115 | BG4: =SUM(BG52,BG56,BG57,BG60:BG61) -> 1071680 | BH4: =SUM(BH52,BH56,BH57,BH60:BH61) -> 1585955 | BI4: =SUM(BI52,BI56,BI57,BI60:BI61) -> 1418404 | BJ4: =SUM(BJ52,BJ56,BJ57,BJ60:BJ61) -> 9074376 | BK4: =SUM(BK52,BK56,BK57,BK60:BK61) -> 9082638 | BM4: =SUM(BM52,BM56,BM57,BM60:BM61) -> 339255 | BN4: =SUM(BN52,BN56,BN57,BN60:BN61) -> 653047 | BO4: =SUM(BO52,BO56,BO57,BO60:BO61) -> 1547497 | BP4: =SUM(BP52,BP56,BP57,BP60:BP61) -> 729763 | BQ4: =SUM(BQ52,BQ56,BQ57,BQ60:BQ61) -> 691721 | BR4: =SUM(BR52,BR56,BR57,BR60:BR61) -> 874382 | BS4: =SUM(BS52,BS56,BS57,BS60:BS61) -> 946814 | BT4: =SUM(BT52,BT56,BT57,BT60:BT61) -> 5782479 | BU4: =SUM(BU52,BU56,BU57,BU60:BU61) -> 5784968 | BW4: 25 Sig Even Months | BX4: =SUM(BX52,BX57,BX60:BX61) -> 32433 | BY4: =SUM(BY52,BY57,BY60:BY61) -> 62967 | BZ4: =SUM(BZ52,BZ57,BZ60:BZ61) -> 121423 | CA4: =SUM(CA52,CA57,CA60:CA61) -> 107647 | CB4: =SUM(CB52,CB57,CB60:CB61) -> 82990 | CC4: =SUM(CC52,CC57,CC60:CC61) -> 86052 | CD4: =SUM(CD52,CD57,CD60:CD61) -> 133470 | CE4: =SUM(CE52,CE57,CE60:CE61) -> 626982 | CF4: =SUM(CF52,CF57,CF60:CF61) -> 622333 | CH4: 25 Sig Even Months | CI4: =SUM(CI52,CI57,CI60:CI61) -> 14554 | CJ4: =SUM(CJ52,CJ57,CJ60:CJ61) -> 30387 | CK4: =SUM(CK52,CK57,CK60:CK61) -> 57719 | CL4: =SUM(CL52,CL57,CL60:CL61) -> 51260 | CM4: =SUM(CM52,CM57,CM60:CM61) -> 37094 | CN4: =SUM(CN52,CN57,CN60:CN61) -> 39100 | CO4: =SUM(CO52,CO57,CO60:CO61) -> 63190 | CP4: =SUM(CP52,CP57,CP60:CP61) -> 293304 | CQ4: =SUM(CQ52,CQ57,CQ60:CQ61) -> 267840 | CS4: 25 Sig Even Months | CT4: =SUM(CT52,CT57,CT60:CT61) -> 17879 | CU4: =SUM(CU52,CU57,CU60:CU61) -> 32580 | CV4: =SUM(CV52,CV57,CV60:CV61) -> 63704 | CW4: =SUM(CW52,CW57,CW60:CW61) -> 56387 | CX4: =SUM(CX52,CX57,CX60:CX61) -> 45896 | CY4: =SUM(CY52,CY57,CY60:CY61) -> 46952 | CZ4: =SUM(CZ52,CZ57,CZ60:CZ61) -> 70280 | DA4: =SUM(DA52,DA57,DA60:DA61) -> 333678 | DB4: =SUM(DB52,DB57,DB60:DB61) -> 354493 | DD4: 25 Sig Even Months | DE4: =SUM(DE52,DE57,DE60:DE61) -> 139243 | DF4: =SUM(DF52,DF57,DF60:DF61) -> 220667 | DG4: =SUM(DG52,DG57,DG60:DG61) -> 430789 | DH4: =SUM(DH52,DH57,DH60:DH61) -> 385348 | DI4: =SUM(DI52,DI57,DI60:DI61) -> 332040 | DJ4: =SUM(DJ52,DJ57,DJ60:DJ61) -> 323709 | DK4: =SUM(DK52,DK57,DK60:DK61) -> 511648 | DL4: =SUM(DL52,DL57,DL60:DL61) -> 2343444 | DM4: =SUM(DM52,DM57,DM60:DM61) -> 2395842 | DO4: 25 Sig Even Months | DP4: =SUM(DP52,DP57,DP60:DP61) -> 0 | DQ4: =SUM(DQ52,DQ57,DQ60:DQ61) -> 0 | DR4: =SUM(DR52,DR57,DR60:DR61) -> 0 | DS4: =SUM(DS52,DS57,DS60:DS61) -> 0 | DT4: =SUM(DT52,DT57,DT60:DT61) -> 0 | DU4: =SUM(DU52,DU57,DU60:DU61) -> 0 | DV4: =SUM(DV52,DV57,DV60:DV61) -> 0 | DW4: =SUM(DW52,DW57,DW60:DW61) -> 0 | DY4: 25 Sig Even Months | DZ4: =SUM(DZ52,DZ57,DZ60:DZ61) -> 0 | EA4: =SUM(EA52,EA57,EA60:EA61) -> 0 | EB4: =SUM(EB52,EB57,EB60:EB61) -> 0 | EC4: =SUM(EC52,EC57,EC60:EC61) -> 0 | ED4: =SUM(ED52,ED57,ED60:ED61) -> 0 | EE4: =SUM(EE52,EE57,EE60:EE61) -> 0 | EF4: =SUM(EF52,EF57,EF60:EF61) -> 0 | EG4: =SUM(EG52,EG57,EG60:EG61) -> 0 | EI4: 25 Sig Even Months | EJ4: =SUM(EJ52,EJ57,EJ60:EJ61) -> 0 | EK4: =SUM(EK52,EK57,EK60:EK61) -> 0 | EL4: =SUM(EL52,EL57,EL60:EL61) -> 0 | EM4: =SUM(EM52,EM57,EM60:EM61) -> 0 | EN4: =SUM(EN52,EN57,EN60:EN61) -> 0 | EO4: =SUM(EO52,EO57,EO60:EO61) -> 0 | EP4: =SUM(EP52,EP57,EP60:EP61) -> 0 | EQ4: =SUM(EQ52,EQ57,EQ60:EQ61) -> 0 | ES4: 25 Sig Even Months | ET4: =SUM(ET52,ET57,ET60:ET61) -> 0 | EU4: =SUM(EU52,EU57,EU60:EU61) -> 0 | EV4: =SUM(EV52,EV57,EV60:EV61) -> 0 | EW4: =SUM(EW52,EW57,EW60:EW61) -> 0 | EX4: =SUM(EX52,EX57,EX60:EX61) -> 0 | EY4: =SUM(EY52,EY57,EY60:EY61) -> 0 | EZ4: =SUM(EZ52,EZ57,EZ60:EZ61) -> 0 | FA4: =SUM(FA52,FA57,FA60:FA61) -> 0 | FC4: 25 Sig Even Months | FD4: =SUM(FD52,FD57,FD60:FD61) -> 0 | FE4: =SUM(FE52,FE57,FE60:FE61) -> 0 | FF4: =SUM(FF52,FF57,FF60:FF61) -> 0 | FG4: =SUM(FG52,FG57,FG60:FG61) -> 0 | FH4: =SUM(FH52,FH57,FH60:FH61) -> 0 | FI4: =SUM(FI52,FI57,FI60:FI61) -> 0 | FJ4: =SUM(FJ52,FJ57,FJ60:FJ61) -> 0 | FK4: =SUM(FK52,FK57,FK60:FK61) -> 0
B5: 25 Non-Sig Even Months | C5: =SUM(C50,C51,C53,C54,C55,C58,C59) -> 2376 | D5: =SUM(D50,D51,D53,D54,D55,D58,D59) -> 3461 | E5: =SUM(E50,E51,E53,E54,E55,E58,E59) -> 9811 | F5: =SUM(F50,F51,F53,F54,F55,F58,F59) -> 4995 | G5: =SUM(G50,G51,G53,G54,G55,G58,G59) -> 5914 | H5: =SUM(H50,H51,H53,H54,H55,H58,H59) -> 4809 | I5: =SUM(I50,I51,I53,I54,I55,I58,I59) -> 7381 | J5: =SUM(J50,J51,J53,J54,J55,J58,J59) -> 39167 | L5: 25 Non-Sig Even Months | M5: =SUM(M50,M51,M53,M54,M55,M56,M58,M59) -> 2707 | N5: =SUM(N50,N51,N53,N54,N55,N56,N58,N59) -> 4046 | O5: =SUM(O50,O51,O53,O54,O55,O56,O58,O59) -> 11316 | P5: =SUM(P50,P51,P53,P54,P55,P56,P58,P59) -> 5805 | Q5: =SUM(Q50,Q51,Q53,Q54,Q55,Q56,Q58,Q59) -> 6848 | R5: =SUM(R50,R51,R53,R54,R55,R56,R58,R59) -> 5503 | S5: =SUM(S50,S51,S53,S54,S55,S56,S58,S59) -> 8586 | T5: =SUM(T50,T51,T53,T54,T55,T56,T58,T59) -> 45267 | V5: 25 Non-Sig Even Months | W5: =SUM(W50,W51,W53,W54,W55,W56,W58,W59) -> 1292763 | X5: =SUM(X50,X51,X53,X54,X55,X56,X58,X59) -> 2156226 | Y5: =SUM(Y50,Y51,Y53,Y54,Y55,Y56,Y58,Y59) -> 4010240 | Z5: =SUM(Z50,Z51,Z53,Z54,Z55,Z56,Z58,Z59) -> 3934524 | AA5: =SUM(AA50,AA51,AA53,AA54,AA55,AA56,AA58,AA59) -> 3468806 | AB5: =SUM(AB50,AB51,AB53,AB54,AB55,AB56,AB58,AB59) -> 3276937 | AC5: =SUM(AC50,AC51,AC53,AC54,AC55,AC56,AC58,AC59) -> 4672138 | AD5: =SUM(AD50,AD51,AD53,AD54,AD55,AD56,AD58,AD59) -> 23579958 | AF5: 25 Non-Sig Even Months | AG5: =SUM(AG50,AG51,AG53,AG54,AG55,AG56,AG58,AG59) -> 1000866 | AH5: =SUM(AH50,AH51,AH53,AH54,AH55,AH56,AH58,AH59) -> 1619270 | AI5: =SUM(AI50,AI51,AI53,AI54,AI55,AI56,AI58,AI59) -> 3040644 | AJ5: =SUM(AJ50,AJ51,AJ53,AJ54,AJ55,AJ56,AJ58,AJ59) -> 2949632 | AK5: =SUM(AK50,AK51,AK53,AK54,AK55,AK56,AK58,AK59) -> 2728596 | AL5: =SUM(AL50,AL51,AL53,AL54,AL55,AL56,AL58,AL59) -> 2499061 | AM5: =SUM(AM50,AM51,AM53,AM54,AM55,AM56,AM58,AM59) -> 3577380 | AN5: =SUM(AN50,AN51,AN53,AN54,AN55,AN56,AN58,AN59) -> 17916133 | AP5: 25 Non-Sig Even Months | AQ5: =SUM(AQ50,AQ51,AQ53,AQ54,AQ55,AQ56,AQ58,AQ59) -> 0 | AR5: =SUM(AR50,AR51,AR53,AR54,AR55,AR56,AR58,AR59) -> 0 | AS5: =SUM(AS50,AS51,AS53,AS54,AS55,AS56,AS58,AS59) -> 0 | AT5: =SUM(AT50,AT51,AT53,AT54,AT55,AT56,AT58,AT59) -> 0 | AU5: =SUM(AU50,AU51,AU53,AU54,AU55,AU56,AU58,AU59) -> 0 | AV5: =SUM(AV50,AV51,AV53,AV54,AV55,AV56,AV58,AV59) -> 0 | AW5: =SUM(AW50,AW51,AW53,AW54,AW55,AW56,AW58,AW59) -> 0 | AX5: =SUM(AX50,AX51,AX53,AX54,AX55,AX56,AX58,AX59) -> 0 | AZ5: 25 Non-Sig Even Months | BA5: =SUM(BA50,BA51,BA53,BA54,BA55,BA58,BA59) -> 1218915 | BC5: =SUM(BC50,BC51,BC53,BC54,BC55,BC58,BC59) -> 775291 | BD5: =SUM(BD50,BD51,BD53,BD54,BD55,BD58,BD59) -> 1180090 | BE5: =SUM(BE50,BE51,BE53,BE54,BE55,BE58,BE59) -> 2941088 | BF5: =SUM(BF50,BF51,BF53,BF54,BF55,BF58,BF59) -> 1465303 | BG5: =SUM(BG50,BG51,BG53,BG54,BG55,BG58,BG59) -> 1401710 | BH5: =SUM(BH50,BH51,BH53,BH54,BH55,BH58,BH59) -> 1990484 | BI5: =SUM(BI50,BI51,BI53,BI54,BI55,BI58,BI59) -> 1920071 | BJ5: =SUM(BJ50,BJ51,BJ53,BJ54,BJ55,BJ58,BJ59) -> 11674037 | BK5: =SUM(BK50,BK51,BK53,BK54,BK55,BK58,BK59) -> 11675625 | BM5: =SUM(BM50,BM51,BM53,BM54,BM55,BM58,BM59) -> 443624 | BN5: =SUM(BN50,BN51,BN53,BN54,BN55,BN58,BN59) -> 849825 | BO5: =SUM(BO50,BO51,BO53,BO54,BO55,BO58,BO59) -> 1863027 | BP5: =SUM(BP50,BP51,BP53,BP54,BP55,BP58,BP59) -> 940680 | BQ5: =SUM(BQ50,BQ51,BQ53,BQ54,BQ55,BQ58,BQ59) -> 929663 | BR5: =SUM(BR50,BR51,BR53,BR54,BR55,BR58,BR59) -> 1086317 | BS5: =SUM(BS50,BS51,BS53,BS54,BS55,BS58,BS59) -> 1278603 | BT5: =SUM(BT50,BT51,BT53,BT54,BT55,BT58,BT59) -> 7391739 | BU5: =SUM(BU50,BU51,BU53,BU54,BU55,BU58,BU59) -> 7392315 | BW5: 25 Non-Sig Even Months | BX5: =SUM(BX50,BX51,BX53,BX54,BX55,BX56,BX58,BX59) -> 56761 | BY5: =SUM(BY50,BY51,BY53,BY54,BY55,BY56,BY58,BY59) -> 119646 | BZ5: =SUM(BZ50,BZ51,BZ53,BZ54,BZ55,BZ56,BZ58,BZ59) -> 218479 | CA5: =SUM(CA50,CA51,CA53,CA54,CA55,CA56,CA58,CA59) -> 212482 | CB5: =SUM(CB50,CB51,CB53,CB54,CB55,CB56,CB58,CB59) -> 155179 | CC5: =SUM(CC50,CC51,CC53,CC54,CC55,CC56,CC58,CC59) -> 163519 | CD5: =SUM(CD50,CD51,CD53,CD54,CD55,CD56,CD58,CD59) -> 260777 | CE5: =SUM(CE50,CE51,CE53,CE54,CE55,CE56,CE58,CE59) -> 1186843 | CF5: =SUM(CF50,CF51,CF53,CF54,CF55,CF56,CF58,CF59) -> 1106428 | CH5: 25 Non-Sig Even Months | CI5: =SUM(CI50,CI51,CI53,CI54,CI55,CI56,CI58,CI59) -> 27727 | CJ5: =SUM(CJ50,CJ51,CJ53,CJ54,CJ55,CJ56,CJ58,CJ59) -> 62162 | CK5: =SUM(CK50,CK51,CK53,CK54,CK55,CK56,CK58,CK59) -> 112357 | CL5: =SUM(CL50,CL51,CL53,CL54,CL55,CL56,CL58,CL59) -> 110391 | CM5: =SUM(CM50,CM51,CM53,CM54,CM55,CM56,CM58,CM59) -> 76494 | CN5: =SUM(CN50,CN51,CN53,CN54,CN55,CN56,CN58,CN59) -> 81994 | CO5: =SUM(CO50,CO51,CO53,CO54,CO55,CO56,CO58,CO59) -> 134632 | CP5: =SUM(CP50,CP51,CP53,CP54,CP55,CP56,CP58,CP59) -> 605757 | CQ5: =SUM(CQ50,CQ51,CQ53,CQ54,CQ55,CQ56,CQ58,CQ59) -> 500900 | CS5: 25 Non-Sig Even Months | CT5: =SUM(CT50,CT51,CT53,CT54,CT55,CT56,CT58,CT59) -> 29034 | CU5: =SUM(CU50,CU51,CU53,CU54,CU55,CU56,CU58,CU59) -> 57484 | CV5: =SUM(CV50,CV51,CV53,CV54,CV55,CV56,CV58,CV59) -> 106122 | CW5: =SUM(CW50,CW51,CW53,CW54,CW55,CW56,CW58,CW59) -> 102091 | CX5: =SUM(CX50,CX51,CX53,CX54,CX55,CX56,CX58,CX59) -> 78685 | CY5: =SUM(CY50,CY51,CY53,CY54,CY55,CY56,CY58,CY59) -> 81525 | CZ5: =SUM(CZ50,CZ51,CZ53,CZ54,CZ55,CZ56,CZ58,CZ59) -> 126145 | DA5: =SUM(DA50,DA51,DA53,DA54,DA55,DA56,DA58,DA59) -> 581086 | DB5: =SUM(DB50,DB51,DB53,DB54,DB55,DB56,DB58,DB59) -> 605528 | DD5: 25 Non-Sig Even Months | DE5: =SUM(DE50,DE51,DE53,DE54,DE55,DE56,DE58,DE59) -> 220613 | DF5: =SUM(DF50,DF51,DF53,DF54,DF55,DF56,DF58,DF59) -> 363790 | DG5: =SUM(DG50,DG51,DG53,DG54,DG55,DG56,DG58,DG59) -> 672457 | DH5: =SUM(DH50,DH51,DH53,DH54,DH55,DH56,DH58,DH59) -> 647557 | DI5: =SUM(DI50,DI51,DI53,DI54,DI55,DI56,DI58,DI59) -> 547518 | DJ5: =SUM(DJ50,DJ51,DJ53,DJ54,DJ55,DJ56,DJ58,DJ59) -> 521178 | DK5: =SUM(DK50,DK51,DK53,DK54,DK55,DK56,DK58,DK59) -> 898576 | DL5: =SUM(DL50,DL51,DL53,DL54,DL55,DL56,DL58,DL59) -> 3871689 | DM5: =SUM(DM50,DM51,DM53,DM54,DM55,DM56,DM58,DM59) -> 3978472 | DO5: 25 Non-Sig Even Months | DP5: =SUM(DP50,DP51,DP53,DP54,DP55,DP56,DP58,DP59) -> 0 | DQ5: =SUM(DQ50,DQ51,DQ53,DQ54,DQ55,DQ56,DQ58,DQ59) -> 0 | DR5: =SUM(DR50,DR51,DR53,DR54,DR55,DR56,DR58,DR59) -> 0 | DS5: =SUM(DS50,DS51,DS53,DS54,DS55,DS56,DS58,DS59) -> 0 | DT5: =SUM(DT50,DT51,DT53,DT54,DT55,DT56,DT58,DT59) -> 0 | DU5: =SUM(DU50,DU51,DU53,DU54,DU55,DU56,DU58,DU59) -> 0 | DV5: =SUM(DV50,DV51,DV53,DV54,DV55,DV56,DV58,DV59) -> 0 | DW5: =SUM(DW50,DW51,DW53,DW54,DW55,DW56,DW58,DW59) -> 0 | DY5: 25 Non-Sig Even Months | DZ5: =SUM(DZ50,DZ51,DZ53,DZ54,DZ55,DZ56,DZ58,DZ59) -> 0 | EA5: =SUM(EA50,EA51,EA53,EA54,EA55,EA56,EA58,EA59) -> 0 | EB5: =SUM(EB50,EB51,EB53,EB54,EB55,EB56,EB58,EB59) -> 0 | EC5: =SUM(EC50,EC51,EC53,EC54,EC55,EC56,EC58,EC59) -> 0 | ED5: =SUM(ED50,ED51,ED53,ED54,ED55,ED56,ED58,ED59) -> 0 | EE5: =SUM(EE50,EE51,EE53,EE54,EE55,EE56,EE58,EE59) -> 0 | EF5: =SUM(EF50,EF51,EF53,EF54,EF55,EF56,EF58,EF59) -> 0 | EG5: =SUM(EG50,EG51,EG53,EG54,EG55,EG56,EG58,EG59) -> 0 | EI5: 25 Non-Sig Even Months | EJ5: =SUM(EJ50,EJ51,EJ53,EJ54,EJ55,EJ56,EJ58,EJ59) -> 0 | EK5: =SUM(EK50,EK51,EK53,EK54,EK55,EK56,EK58,EK59) -> 0 | EL5: =SUM(EL50,EL51,EL53,EL54,EL55,EL56,EL58,EL59) -> 0 | EM5: =SUM(EM50,EM51,EM53,EM54,EM55,EM56,EM58,EM59) -> 0 | EN5: =SUM(EN50,EN51,EN53,EN54,EN55,EN56,EN58,EN59) -> 0 | EO5: =SUM(EO50,EO51,EO53,EO54,EO55,EO56,EO58,EO59) -> 0 | EP5: =SUM(EP50,EP51,EP53,EP54,EP55,EP56,EP58,EP59) -> 0 | EQ5: =SUM(EQ50,EQ51,EQ53,EQ54,EQ55,EQ56,EQ58,EQ59) -> 0 | ES5: 25 Non-Sig Even Months | ET5: =SUM(ET50,ET51,ET53,ET54,ET55,ET56,ET58,ET59) -> 0 | EU5: =SUM(EU50,EU51,EU53,EU54,EU55,EU56,EU58,EU59) -> 0 | EV5: =SUM(EV50,EV51,EV53,EV54,EV55,EV56,EV58,EV59) -> 0 | EW5: =SUM(EW50,EW51,EW53,EW54,EW55,EW56,EW58,EW59) -> 0 | EX5: =SUM(EX50,EX51,EX53,EX54,EX55,EX56,EX58,EX59) -> 0 | EY5: =SUM(EY50,EY51,EY53,EY54,EY55,EY56,EY58,EY59) -> 0 | EZ5: =SUM(EZ50,EZ51,EZ53,EZ54,EZ55,EZ56,EZ58,EZ59) -> 0 | FA5: =SUM(FA50,FA51,FA53,FA54,FA55,FA56,FA58,FA59) -> 0 | FC5: 25 Non-Sig Even Months | FD5: =SUM(FD50,FD51,FD53,FD54,FD55,FD56,FD58,FD59) -> 0 | FE5: =SUM(FE50,FE51,FE53,FE54,FE55,FE56,FE58,FE59) -> 0 | FF5: =SUM(FF50,FF51,FF53,FF54,FF55,FF56,FF58,FF59) -> 0 | FG5: =SUM(FG50,FG51,FG53,FG54,FG55,FG56,FG58,FG59) -> 0 | FH5: =SUM(FH50,FH51,FH53,FH54,FH55,FH56,FH58,FH59) -> 0 | FI5: =SUM(FI50,FI51,FI53,FI54,FI55,FI56,FI58,FI59) -> 0 | FJ5: =SUM(FJ50,FJ51,FJ53,FJ54,FJ55,FJ56,FJ58,FJ59) -> 0 | FK5: =SUM(FK50,FK51,FK53,FK54,FK55,FK56,FK58,FK59) -> 0
B6: Rates: | L6: Rates: | V6: Rates: | AF6: Rates: | AP6: Rates: | AZ6: Rates: | BC6: Action - Sales Rates | BM6: Action - Sales Rates | BW6: Action - Sales Rates | CH6: Action - Sales Rates | CS6: Action - Sales Rates | DD6: Action - Sales Rates | DO6: Rates: | DY6: Rates: | EI6: Rates: | ES6: Rates: | FC6: Rates:
B7: 25 Sig Even Months | L7: 25 Sig Even Months | V7: 25 Sig Even Months | AF7: 25 Sig Even Months | AP7: 25 Sig Even Months | AZ7: 25 Sig Even Months | BC7: =C4/BC4 -> 0.0032178275 | BD7: =D4/BD4 -> 0.0033426148 | BE7: =E4/BE4 -> 0.0037765592 | BF7: =F4/BF4 -> 0.0038066386 | BG7: =G4/BG4 -> 0.0050593461 | BH7: =H4/BH4 -> 0.0027541765 | BI7: =I4/BI4 -> 0.0047870705 | BJ7: =J4/BJ4 -> 0.0038478679 | BK7: =J4/BK4 -> 0.0038443677 | BM7: =C4/BM4 -> 0.0057596793 | BN7: =D4/BN4 -> 0.0047132902 | BO7: =E4/BO4 -> 0.0057622083 | BP7: =F4/BP4 -> 0.0057854399 | BQ7: =G4/BQ4 -> 0.0078384204 | BR7: =H4/BR4 -> 0.0049955283 | BS7: =I4/BS4 -> 0.0071714191 | BT7: =J4/BT4 -> 0.0060384136 | BU7: =J4/BU4 -> 0.0060358156 | BW7: 25 Sig Even Months | BX7: =M4/BX4 -> 0.050041624 | BY7: =N4/BY4 -> 0.039592167 | BZ7: =O4/BZ4 -> 0.061042801 | CA7: =P4/CA4 -> 0.031696192 | CB7: =Q4/CB4 -> 0.054078805 | CC7: =R4/CC4 -> 0.042695115 | CD7: =S4/CD4 -> 0.041844609 | CE7: =T4/CE4 -> 0.045961447 | CF7: =T4/CF4 -> 0.046304792 | CH7: 25 Sig Even Months | CI7: =M4/CI4 -> 0.11151573 | CJ7: =N4/CJ4 -> 0.082041663 | CK7: =O4/CK4 -> 0.12841525 | CL7: =P4/CL4 -> 0.066562622 | CM7: =Q4/CM4 -> 0.12098992 | CN7: =R4/CN4 -> 0.093964194 | CO7: =S4/CO4 -> 0.088384238 | CP7: =T4/CP4 -> 0.098249598 | CQ7: =T4/CQ4 -> 0.10759035 | CS7: 25 Sig Even Months | CT7: =M4/CT4 -> 0.090776889 | CU7: =N4/CU4 -> 0.076519337 | CV7: =O4/CV4 -> 0.11635062 | CW7: =P4/CW4 -> 0.060510401 | CX7: =Q4/CX4 -> 0.097786299 | CY7: =R4/CY4 -> 0.078250128 | CZ7: =S4/CZ4 -> 0.079467843 | DA7: =T4/DA4 -> 0.086361702 | DB7: =T4/DB4 -> 0.081290745 | DD7: 25 Sig Even Months | DE7: =M4/DE4 -> 0.011655882 | DF7: =N4/DF4 -> 0.011297566 | DG7: =O4/DG4 -> 0.017205639 | DH7: =P4/DH4 -> 0.0088543343 | DI7: =Q4/DI4 -> 0.013516444 | DJ7: =R4/DJ4 -> 0.0113497 | DK7: =S4/DK4 -> 0.010915708 | DL7: =T4/DL4 -> 0.012296859 | DM7: =T4/DM4 -> 0.012027922 | DO7: 25 Sig Even Months | DY7: 25 Sig Even Months | EI7: 25 Sig Even Months | ES7: 25 Sig Even Months | FC7: 25 Sig Even Months
B8: 25 Non-Sig Even Months | L8: 25 Non-Sig Even Months | V8: 25 Non-Sig Even Months | AF8: 25 Non-Sig Even Months | AP8: 25 Non-Sig Even Months | AZ8: 25 Non-Sig Even Months | BC8: =C5/BC5 -> 0.0030646557 | BD8: =D5/BD5 -> 0.0029328272 | BE8: =E5/BE5 -> 0.0033358403 | BF8: =F5/BF5 -> 0.0034088513 | BG8: =G5/BG5 -> 0.0042191323 | BH8: =H5/BH5 -> 0.0024159953 | BI8: =I5/BI5 -> 0.0038441287 | BJ8: =J5/BJ5 -> 0.0033550519 | BK8: =J5/BK5 -> 0.0033545956 | BM8: =C5/BM5 -> 0.005355887 | BN8: =D5/BN5 -> 0.0040726032 | BO8: =E5/BO5 -> 0.0052661609 | BP8: =F5/BP5 -> 0.0053099885 | BQ8: =G5/BQ5 -> 0.006361445 | BR8: =H5/BR5 -> 0.0044268846 | BS8: =I5/BS5 -> 0.0057727066 | BT8: =J5/BT5 -> 0.0052987531 | BU8: =J5/BU5 -> 0.0052983402 | BW8: 25 Non-Sig Even Months | BX8: =M5/BX5 -> 0.047691196 | BY8: =N5/BY5 -> 0.033816425 | BZ8: =O5/BZ5 -> 0.051794452 | CA8: =P5/CA5 -> 0.027319961 | CB8: =Q5/CB5 -> 0.044129682 | CC8: =R5/CC5 -> 0.033653582 | CD8: =S5/CD5 -> 0.032924683 | CE8: =T5/CE5 -> 0.038140681 | CF8: =T5/CF5 -> 0.040912739 | CH8: 25 Non-Sig Even Months | CI8: =M5/CI5 -> 0.097630468 | CJ8: =N5/CJ5 -> 0.065087996 | CK8: =O5/CK5 -> 0.10071469 | CL8: =P5/CL5 -> 0.052585809 | CM8: =Q5/CM5 -> 0.089523361 | CN8: =R5/CN5 -> 0.067114667 | CO8: =S5/CO5 -> 0.063773843 | CP8: =T5/CP5 -> 0.074727985 | CQ8: =T5/CQ5 -> 0.090371332 | CS8: 25 Non-Sig Even Months | CT8: =M5/CT5 -> 0.093235517 | CU8: =N5/CU5 -> 0.070384803 | CV8: =O5/CV5 -> 0.10663199 | CW8: =P5/CW5 -> 0.056861036 | CX8: =Q5/CX5 -> 0.087030565 | CY8: =R5/CY5 -> 0.067500767 | CZ8: =S5/CZ5 -> 0.068064529 | DA8: =T5/DA5 -> 0.077900689 | DB8: =T5/DB5 -> 0.074756246 | DD8: 25 Non-Sig Even Months | DE8: =M5/DE5 -> 0.012270356 | DF8: =N5/DF5 -> 0.011121801 | DG8: =O5/DG5 -> 0.016827842 | DH8: =P5/DH5 -> 0.0089644618 | DI8: =Q5/DI5 -> 0.012507351 | DJ8: =R5/DJ5 -> 0.010558773 | DK8: =S5/DK5 -> 0.0095551183 | DL8: =T5/DL5 -> 0.011691797 | DM8: =T5/DM5 -> 0.011377986 | DO8: 25 Non-Sig Even Months | DY8: 25 Non-Sig Even Months | EI8: 25 Non-Sig Even Months | ES8: 25 Non-Sig Even Months | FC8: 25 Non-Sig Even Months
B9: % of total FY: | C9: =C3/$J3 -> 0.058447168 | D9: =D3/$J3 -> 0.088264673 | E9: =E3/$J3 -> 0.25279413 | F9: =F3/$J3 -> 0.12441283 | G9: =G3/$J3 -> 0.1530155 | H9: =H3/$J3 -> 0.1238729 | I9: =I3/$J3 -> 0.19128287 | J9: =J3/$J3 -> 1 | L9: % of total FY: | M9: =M3/T3 -> 0.058447168 | N9: =N3/T3 -> 0.088264673 | O9: =O3/T3 -> 0.25279413 | P9: =P3/T3 -> 0.12441283 | Q9: =Q3/T3 -> 0.1530155 | R9: =R3/T3 -> 0.1238729 | S9: =S3/T3 -> 0.19128287 | T9: =T3/T3 -> 1 | V9: % of total FY: | W9: =W3/AD3 -> 0.0554635 | X9: =X3/AD3 -> 0.091298465 | Y9: =Y3/AD3 -> 0.17174977 | Z9: =Z3/AD3 -> 0.16488126 | AA9: =AA3/AD3 -> 0.14992158 | AB9: =AB3/AD3 -> 0.13918756 | AC9: =AC3/AD3 -> 0.1964111 | AD9: =AD3/AD3 -> 1 | AF9: % of total FY: | AG9: =AG3/AN3 -> 0.056441402 | AH9: =AH3/AN3 -> 0.090433897 | AI9: =AI3/AN3 -> 0.17191391 | AJ9: =AJ3/AN3 -> 0.16302416 | AK9: =AK3/AN3 -> 0.15411545 | AL9: =AL3/AN3 -> 0.14071199 | AM9: =AM3/AN3 -> 0.19742364 | AN9: =AN3/AN3 -> 1 | AP9: % of total FY: | AQ9: =AQ3/AX3 -> #DIV/0! | AR9: =AR3/AX3 -> #DIV/0! | AS9: =AS3/AX3 -> #DIV/0! | AT9: =AT3/AX3 -> #DIV/0! | AU9: =AU3/AX3 -> #DIV/0! | AV9: =AV3/AX3 -> #DIV/0! | AW9: =AW3/AX3 -> #DIV/0! | AX9: =AX3/AX3 -> #DIV/0! | AZ9: % of total FY: | BC9: =BC3/BJ3 -> 0.066633193 | BD9: =BD3/BJ3 -> 0.10125719 | BE9: =BE3/BJ3 -> 0.2555488 | BF9: =BF3/BJ3 -> 0.12407783 | BG9: =BG3/BJ3 -> 0.11920864 | BH9: =BH3/BJ3 -> 0.17237169 | BI9: =BI3/BJ3 -> 0.16090267 | BJ9: =BJ3/BJ3 -> 1 | BK9: =BK3/BK3 -> 1 | BM9: =BM3/BT3 -> 0.059425083 | BN9: =BN3/BT3 -> 0.11407675 | BO9: =BO3/BT3 -> 0.25887867 | BP9: =BP3/BT3 -> 0.12679637 | BQ9: =BQ3/BT3 -> 0.1230725 | BR9: =BR3/BT3 -> 0.14882849 | BS9: =BS3/BT3 -> 0.16892213 | BT9: =BT3/BT3 -> 1 | BU9: =BU3/BU3 -> 1 | BW9: % of total FY: | BX9: =BX3/CE3 -> 0.049174534 | BY9: =BY3/CE3 -> 0.1006784 | BZ9: =BZ3/CE3 -> 0.18739515 | CA9: =CA3/CE3 -> 0.17649387 | CB9: =CB3/CE3 -> 0.1313076 | CC9: =CC3/CE3 -> 0.13759376 | CD9: =CD3/CE3 -> 0.21735669 | CE9: =CE3/CE3 -> 1 | CF9: =CF3/CF3 -> 1 | CH9: % of total FY: | CI9: =CI3/CP3 -> 0.047027955 | CJ9: =CJ3/CP3 -> 0.10293962 | CK9: =CK3/CP3 -> 0.1891707 | CL9: =CL3/CP3 -> 0.17979981 | CM9: =CM3/CP3 -> 0.1263407 | CN9: =CN3/CP3 -> 0.13468941 | CO9: =CO3/CP3 -> 0.22003179 | CP9: =CP3/CP3 -> 1 | CQ9: =CQ3/CQ3 -> 1 | CS9: % of total FY: | CT9: =CT3/DA3 -> 0.051284266 | CU9: =CU3/DA3 -> 0.098455995 | CV9: =CV3/DA3 -> 0.18565007 | CW9: =CW3/DA3 -> 0.17324468 | CX9: =CX3/DA3 -> 0.13618922 | CY9: =CY3/DA3 -> 0.14044825 | CZ9: =CZ3/DA3 -> 0.21472751 | DA9: =DA3/DA3 -> 1 | DB9: =DB3/DB3 -> 1 | DD9: % of total FY '25: | DE9: =DE3/DL3 -> 0.057899968 | DF9: =DF3/DL3 -> 0.09403773 | DG9: =DG3/DL3 -> 0.17750964 | DH9: =DH3/DL3 -> 0.16619194 | DI9: =DI3/DL3 -> 0.14151877 | DJ9: =DJ3/DL3 -> 0.13594029 | DK9: =DK3/DL3 -> 0.22690166 | DL9: =DL3/DL3 -> 1 | DM9: =DM3/DM3 -> 1 | DO9: % of total FY: | DP9: =DP3/DW3 -> #DIV/0! | DQ9: =DQ3/DW3 -> #DIV/0! | DR9: =DR3/DW3 -> #DIV/0! | DS9: =DS3/DW3 -> #DIV/0! | DT9: =DT3/DW3 -> #DIV/0! | DU9: =DU3/DW3 -> #DIV/0! | DV9: =DV3/DW3 -> #DIV/0! | DW9: =DW3/DW3 -> #DIV/0! | DY9: % of total FY: | DZ9: =DZ3/EG3 -> #DIV/0! | EA9: =EA3/EG3 -> #DIV/0! | EB9: =EB3/EG3 -> #DIV/0! | EC9: =EC3/EG3 -> #DIV/0! | ED9: =ED3/EG3 -> #DIV/0! | EE9: =EE3/EG3 -> #DIV/0! | EF9: =EF3/EG3 -> #DIV/0! | EG9: =EG3/EG3 -> #DIV/0! | EI9: % of total FY: | EJ9: =EJ3/EQ3 -> #DIV/0! | EK9: =EK3/EQ3 -> #DIV/0! | EL9: =EL3/EQ3 -> #DIV/0! | EM9: =EM3/EQ3 -> #DIV/0! | EN9: =EN3/EQ3 -> #DIV/0! | EO9: =EO3/EQ3 -> #DIV/0! | EP9: =EP3/EQ3 -> #DIV/0! | EQ9: =EQ3/EQ3 -> #DIV/0! | ES9: % of total FY: | ET9: =ET3/FA3 -> #DIV/0! | EU9: =EU3/FA3 -> #DIV/0! | EV9: =EV3/FA3 -> #DIV/0! | EW9: =EW3/FA3 -> #DIV/0! | EX9: =EX3/FA3 -> #DIV/0! | EY9: =EY3/FA3 -> #DIV/0! | EZ9: =EZ3/FA3 -> #DIV/0! | FA9: =FA3/FA3 -> #DIV/0! | FC9: % of total FY: | FD9: =FD3/FK3 -> #DIV/0! | FE9: =FE3/FK3 -> #DIV/0! | FF9: =FF3/FK3 -> #DIV/0! | FG9: =FG3/FK3 -> #DIV/0! | FH9: =FH3/FK3 -> #DIV/0! | FI9: =FI3/FK3 -> #DIV/0! | FJ9: =FJ3/FK3 -> #DIV/0! | FK9: =FK3/FK3 -> #DIV/0!
B12: Sales (T3 Timeframes) | L12: Sales (T1 Timeframes) | V12: T1 Site Visits | AF12: VLPs | AP12: VLPs | In-Market Only | AZ12: T3 SV + VDPs | BC12: T3 Sales Visits | BM12: T3 VDPs | BW12: 2026 T1 HVAs |Total | CH12: 2026 HVAs |T1 to T3 Referrals | CS12: 2026 HVAs |VDP Visits | DD12: 2026 MVAs | (total 7x actions) | DO12: 2026 MVAs | (In-Market Only) | DY12: Leads | EI12: Endemic VDPs | ES12: Total Shop Goals | Total = T3 Referrals + T1 VDPs + Sales Visits | Models = T3 Referrals + T1 VDPs + T3 VDPs | FC12: Total Research Goals | T1 MVAs + Endemic VDPs
C13: Mountain Region | D13: Mid Atlantic Region | E13: South Region | F13: Central Region | G13: West Region | H13: South Central Region | I13: East Region | J13: Total | M13: Mountain Region | N13: Mid Atlantic Region | O13: South Region | P13: Central Region | Q13: West Region | R13: South Central Region | S13: East Region | T13: Total | W13: Mountain Region | X13: Mid Atlantic Region | Y13: South Region | Z13: Central Region | AA13: West Region | AB13: South Central Region | AC13: East Region | AD13: Total | AG13: Mountain Region | AH13: Mid Atlantic Region | AI13: South Region | AJ13: Central Region | AK13: West Region | AL13: South Central Region | AM13: East Region | AN13: Total | AQ13: Mountain Region | AR13: Mid Atlantic Region | AS13: South Region | AT13: Central Region | AU13: West Region | AV13: South Central Region | AW13: East Region | AX13: Total | BA13: Total | BC13: Mountain Region | BD13: Mid Atlantic Region | BE13: South Region | BF13: Central Region | BG13: West Region | BH13: South Central Region | BI13: East Region | BJ13: Sum of Regions | BK13: National | BM13: Mountain Region | BN13: Mid Atlantic Region | BO13: South Region | BP13: Central Region | BQ13: West Region | BR13: South Central Region | BS13: East Region | BT13: Sum of Regions | BU13: National | BX13: Mountain Region | BY13: Mid Atlantic Region | BZ13: South Region | CA13: Central Region | CB13: West Region | CC13: South Central Region | CD13: East Region | CE13: Sum of Regions | CF13: National | CI13: Mountain Region | CJ13: Mid Atlantic Region | CK13: South Region | CL13: Central Region | CM13: West Region | CN13: South Central Region | CO13: East Region | CP13: Sum of Regions | CQ13: National | CT13: Mountain Region | CU13: Mid Atlantic Region | CV13: South Region | CW13: Central Region | CX13: West Region | CY13: South Central Region | CZ13: East Region | DA13: Sum of Regions | DB13: National | DE13: Mountain Region | DF13: Mid Atlantic Region | DG13: South Region | DH13: Central Region | DI13: West Region | DJ13: South Central Region | DK13: East Region | DL13: Sum of Regions | DM13: National | DP13: Mountain Region | DQ13: Mid Atlantic Region | DR13: South Region | DS13: Central Region | DT13: West Region | DU13: South Central Region | DV13: East Region | DW13: Total | DZ13: Mountain Region | EA13: Mid Atlantic Region | EB13: South Region | EC13: Central Region | ED13: West Region | EE13: South Central Region | EF13: East Region | EG13: Total | EJ13: Mountain Region | EK13: Mid Atlantic Region | EL13: South Region | EM13: Central Region | EN13: West Region | EO13: South Central Region | EP13: East Region | EQ13: Total | ET13: Mountain Region | EU13: Mid Atlantic Region | EV13: South Region | EW13: Central Region | EX13: West Region | EY13: South Central Region | EZ13: East Region | FA13: Total | FD13: Mountain Region | FE13: Mid Atlantic Region | FF13: South Region | FG13: Central Region | FH13: West Region | FI13: South Central Region | FJ13: East Region | FK13: Total
B14: 44562 | J14: =SUM(C14:I14) -> 0 | L14: 44562 | V14: 44562 | AF14: 44562 | AP14: 44562 | AZ14: 44562 | BW14: 44562 | CH14: 44562 | CS14: 44562 | DD14: 44562 | DO14: 44562 | DY14: 44562 | EI14: 44562 | ES14: 44562 | FC14: 44562
B15: 44593 | J15: =SUM(C15:I15) -> 0 | L15: 44593 | V15: 44593 | AF15: 44593 | AP15: 44593 | AZ15: 44593 | BW15: 44593 | CH15: 44593 | CS15: 44593 | DD15: 44593 | DO15: 44593 | DY15: 44593 | EI15: 44593 | ES15: 44593 | FC15: 44593
B16: 44621 | J16: =SUM(C16:I16) -> 0 | L16: 44621 | V16: 44621 | AF16: 44621 | AP16: 44621 | AZ16: 44621 | BW16: 44621 | CH16: 44621 | CS16: 44621 | DD16: 44621 | DO16: 44621 | DY16: 44621 | EI16: 44621 | ES16: 44621 | FC16: 44621
B17: 44652 | J17: =SUM(C17:I17) -> 0 | L17: 44652 | V17: 44652 | AF17: 44652 | AP17: 44652 | AZ17: 44652 | BW17: 44652 | CH17: 44652 | CS17: 44652 | DD17: 44652 | DO17: 44652 | DY17: 44652 | EI17: 44652 | ES17: 44652 | FC17: 44652
B18: 44682 | J18: =SUM(C18:I18) -> 0 | L18: 44682 | V18: 44682 | AF18: 44682 | AP18: 44682 | AZ18: 44682 | BW18: 44682 | CH18: 44682 | CS18: 44682 | DD18: 44682 | DO18: 44682 | DY18: 44682 | EI18: 44682 | ES18: 44682 | FC18: 44682
B19: 44713 | J19: =SUM(C19:I19) -> 0 | L19: 44713 | V19: 44713 | AF19: 44713 | AP19: 44713 | AZ19: 44713 | BW19: 44713 | CH19: 44713 | CS19: 44713 | DD19: 44713 | DO19: 44713 | DY19: 44713 | EI19: 44713 | ES19: 44713 | FC19: 44713
B20: 44743 | J20: =SUM(C20:I20) -> 0 | L20: 44743 | V20: 44743 | AF20: 44743 | AP20: 44743 | AZ20: 44743 | BW20: 44743 | CH20: 44743 | CS20: 44743 | DD20: 44743 | DO20: 44743 | DY20: 44743 | EI20: 44743 | ES20: 44743 | FC20: 44743
B21: 44774 | J21: =SUM(C21:I21) -> 0 | L21: 44774 | V21: 44774 | AF21: 44774 | AP21: 44774 | AZ21: 44774 | BW21: 44774 | CH21: 44774 | CS21: 44774 | DD21: 44774 | DO21: 44774 | DY21: 44774 | EI21: 44774 | ES21: 44774 | FC21: 44774
B22: 44805 | J22: =SUM(C22:I22) -> 0 | L22: 44805 | V22: 44805 | AF22: 44805 | AP22: 44805 | AZ22: 44805 | BW22: 44805 | CH22: 44805 | CS22: 44805 | DD22: 44805 | DO22: 44805 | DY22: 44805 | EI22: 44805 | ES22: 44805 | FC22: 44805
B23: 44835 | J23: =SUM(C23:I23) -> 0 | L23: 44835 | V23: 44835 | AF23: 44835 | AP23: 44835 | AZ23: 44835 | BW23: 44835 | CH23: 44835 | CS23: 44835 | DD23: 44835 | DO23: 44835 | DY23: 44835 | EI23: 44835 | ES23: 44835 | FC23: 44835
B24: 44866 | J24: =SUM(C24:I24) -> 0 | L24: 44866 | V24: 44866 | AF24: 44866 | AP24: 44866 | AZ24: 44866 | BW24: 44866 | CH24: 44866 | CS24: 44866 | DD24: 44866 | DO24: 44866 | DY24: 44866 | EI24: 44866 | ES24: 44866 | FC24: 44866
B25: 44896 | J25: =SUM(C25:I25) -> 0 | L25: 44896 | V25: 44896 | AF25: 44896 | AP25: 44896 | AZ25: 44896 | BW25: 44896 | CH25: 44896 | CS25: 44896 | DD25: 44896 | DO25: 44896 | DY25: 44896 | EI25: 44896 | ES25: 44896 | FC25: 44896
B26: 44927 | J26: =SUM(C26:I26) -> 0 | L26: 44927 | V26: 44927 | AF26: 44927 | AP26: 44927 | AZ26: 44927 | BA26: =BC26+BM26 -> 0 | BW26: 44927 | CH26: 44927 | CS26: 44927 | DD26: 44927 | DO26: 44927 | DY26: 44927 | EI26: 44927 | ES26: 44927 | FC26: 44927
B27: 44958 | J27: =SUM(C27:I27) -> 0 | L27: 44958 | V27: 44958 | AF27: 44958 | AP27: 44958 | AZ27: 44958 | BA27: =BC27+BM27 -> 0 | BW27: 44958 | CH27: 44958 | CS27: 44958 | DD27: 44958 | DO27: 44958 | DY27: 44958 | EI27: 44958 | ES27: 44958 | FC27: 44958
B28: 44986 | J28: =SUM(C28:I28) -> 0 | L28: 44986 | V28: 44986 | AF28: 44986 | AP28: 44986 | AZ28: 44986 | BA28: =BC28+BM28 -> 0 | BW28: 44986 | CH28: 44986 | CS28: 44986 | DD28: 44986 | DO28: 44986 | DY28: 44986 | EI28: 44986 | ES28: 44986 | FC28: 44986
B29: 45017 | J29: =SUM(C29:I29) -> 0 | L29: 45017 | V29: 45017 | AF29: 45017 | AP29: 45017 | AZ29: 45017 | BA29: =BC29+BM29 -> 0 | BW29: 45017 | CH29: 45017 | CS29: 45017 | DD29: 45017 | DO29: 45017 | DY29: 45017 | EI29: 45017 | ES29: 45017 | FC29: 45017
B30: 45047 | J30: =SUM(C30:I30) -> 0 | L30: 45047 | V30: 45047 | AF30: 45047 | AP30: 45047 | AZ30: 45047 | BA30: =BC30+BM30 -> 0 | BW30: 45047 | CH30: 45047 | CS30: 45047 | DD30: 45047 | DO30: 45047 | DY30: 45047 | EI30: 45047 | ES30: 45047 | FC30: 45047
B31: 45078 | J31: =SUM(C31:I31) -> 0 | L31: 45078 | V31: 45078 | AF31: 45078 | AP31: 45078 | AZ31: 45078 | BA31: =BC31+BM31 -> 0 | BW31: 45078 | CH31: 45078 | CS31: 45078 | DD31: 45078 | DO31: 45078 | DY31: 45078 | EI31: 45078 | ES31: 45078 | FC31: 45078
B32: 45108 | J32: =SUM(C32:I32) -> 0 | L32: 45108 | V32: 45108 | AF32: 45108 | AP32: 45108 | AZ32: 45108 | BA32: =BC32+BM32 -> 0 | BW32: 45108 | CH32: 45108 | CS32: 45108 | DD32: 45108 | DO32: 45108 | DY32: 45108 | EI32: 45108 | ES32: 45108 | FC32: 45108
B33: 45139 | J33: =SUM(C33:I33) -> 0 | L33: 45139 | V33: 45139 | AF33: 45139 | AP33: 45139 | AZ33: 45139 | BA33: =BC33+BM33 -> 0 | BW33: 45139 | CH33: 45139 | CS33: 45139 | DD33: 45139 | DO33: 45139 | DY33: 45139 | EI33: 45139 | ES33: 45139 | FC33: 45139
B34: 45170 | J34: =SUM(C34:I34) -> 0 | L34: 45170 | V34: 45170 | AF34: 45170 | AP34: 45170 | AZ34: 45170 | BA34: =BC34+BM34 -> 0 | BW34: 45170 | CH34: 45170 | CS34: 45170 | DD34: 45170 | DO34: 45170 | DY34: 45170 | EI34: 45170 | ES34: 45170 | FC34: 45170
B35: 45200 | J35: =SUM(C35:I35) -> 0 | L35: 45200 | V35: 45200 | AF35: 45200 | AP35: 45200 | AZ35: 45200 | BA35: =BC35+BM35 -> 0 | BW35: 45200 | CH35: 45200 | CS35: 45200 | DD35: 45200 | DO35: 45200 | DY35: 45200 | EI35: 45200 | ES35: 45200 | FC35: 45200
B36: 45231 | J36: =SUM(C36:I36) -> 0 | L36: 45231 | V36: 45231 | AF36: 45231 | AP36: 45231 | AZ36: 45231 | BA36: =BC36+BM36 -> 0 | BW36: 45231 | CH36: 45231 | CS36: 45231 | DD36: 45231 | DO36: 45231 | DY36: 45231 | EI36: 45231 | ES36: 45231 | FC36: 45231
B37: 45261 | J37: =SUM(C37:I37) -> 0 | L37: 45261 | V37: 45261 | AF37: 45261 | AP37: 45261 | AZ37: 45261 | BA37: =BC37+BM37 -> 0 | BW37: 45261 | CH37: 45261 | CS37: 45261 | DD37: 45261 | DO37: 45261 | DY37: 45261 | EI37: 45261 | ES37: 45261 | FC37: 45261
... B49: 45627 | J49: =SUM(C49:I49) -> 0 | L49: 45627 | V49: 45627 | AF49: 45627 | AP49: 45627 | AZ49: 45627 | BA49: =BC49+BM49 -> 0 | BW49: 45627 | CH49: 45627 | CS49: 45627 | DD49: 45627 | DO49: 45627 | DY49: 45627 | EI49: 45627 | ES49: 45627 | FC49: 45627
B50: 45658 | C50: 257 | D50: 367 | E50: 1227 | F50: 524 | G50: 691 | H50: 520 | I50: 856 | J50: 4547 | L50: 45658 | M50: 257 | N50: 367 | O50: 1227 | P50: 524 | Q50: 691 | R50: 520 | S50: 856 | T50: 4547 | V50: 45658 | W50: 125208 | X50: 214787 | Y50: 381823 | Z50: 350591 | AA50: 299511 | AB50: 304164 | AC50: 440973 | AD50: 2221670 | AF50: 45658 | AG50: 99328 | AH50: 162487 | AI50: 297408 | AJ50: 265503 | AK50: 237216 | AL50: 236733 | AM50: 339852 | AN50: 1707959 | AP50: 45658 | AZ50: 45658 | BA50: =BC50+BM50 -> 161875 | BC50: 104537 | BD50: 189792 | BE50: 383829 | BF50: 198589 | BG50: 213243 | BH50: 264077 | BI50: 304831 | BJ50: =SUM(BC50:BI50) -> 1658898 | BK50: ='Historic Data'!BM47 -> 1659038 | BM50: 57338 | BN50: 138399 | BO50: 218507 | BP50: 128644 | BQ50: 125316 | BR50: 136719 | BS50: 203230 | BT50: =SUM(BM50:BS50) -> 1008153 | BU50: ='Historic Data'!BO47 -> 1008161 | BW50: 45658 | BX50: =CI50+CT50 -> 7020 | BY50: =CJ50+CU50 -> 15049 | BZ50: =CK50+CV50 -> 27131 | CA50: =CL50+CW50 -> 24181 | CB50: =CM50+CX50 -> 19444 | CC50: =CN50+CY50 -> 19838 | CD50: =CO50+CZ50 -> 31697 | CE50: =SUM(BX50:CD50) -> 144360 | CF50: =CQ50+DB50 -> 128664 | CH50: 45658 | CI50: 3280 | CJ50: 7445 | CK50: 13664 | CL50: 12082 | CM50: 9618 | CN50: 9753 | CO50: 16098 | CP50: =SUM(CI50:CO50) -> 71940 | CQ50: ='Historic Data'!CZ47 -> 64501 | CS50: 45658 | CT50: 3740 | CU50: 7604 | CV50: 13467 | CW50: 12099 | CX50: 9826 | CY50: 10085 | CZ50: 15599 | DA50: =SUM(CT50:CZ50) -> 72420 | DB50: ='Historic Data'!DL47 -> 64163 | DD50: 45658 | DE50: 22229 | DF50: 39360 | DG50: 69553 | DH50: 60115 | DI50: 56815 | DJ50: 50421 | DK50: 89651 | DL50: =SUM(DE50:DK50) -> 388144 | DM50: ='Historic Data'!DX47 -> 402930 | DO50: 45658 | DY50: 45658 | EI50: 45658 | ES50: 45658 | FC50: 45658
B51: 45689 | C51: 282 | D51: 456 | E51: 1370 | F51: 633 | G51: 784 | H51: 633 | I51: 882 | J51: 5096 | L51: 45689 | M51: 282 | N51: 456 | O51: 1370 | P51: 633 | Q51: 784 | R51: 633 | S51: 882 | T51: 5096 | V51: 45689 | W51: 121425 | X51: 204394 | Y51: 376013 | Z51: 355018 | AA51: 299075 | AB51: 286105 | AC51: 422317 | AD51: 2151985 | AF51: 45689 | AG51: 94181 | AH51: 150495 | AI51: 285264 | AJ51: 264042 | AK51: 233494 | AL51: 216901 | AM51: 314855 | AN51: 1616326 | AP51: 45689 | AZ51: 45689 | BA51: =BC51+BM51 -> 155750 | BC51: 99936 | BD51: 172589 | BE51: 368545 | BF51: 198038 | BG51: 201429 | BH51: 248403 | BI51: 287540 | BJ51: =SUM(BC51:BI51) -> 1576480 | BK51: ='Historic Data'!BM48 -> 1576643 | BM51: 55814 | BN51: 132480 | BO51: 209387 | BP51: 132223 | BQ51: 126731 | BR51: 135737 | BS51: 194655 | BT51: =SUM(BM51:BS51) -> 987027 | BU51: ='Historic Data'!BO48 -> 987033 | BW51: 45689 | BX51: =CI51+CT51 -> 7192 | BY51: =CJ51+CU51 -> 14806 | BZ51: =CK51+CV51 -> 26193 | CA51: =CL51+CW51 -> 24883 | CB51: =CM51+CX51 -> 18426 | CC51: =CN51+CY51 -> 18749 | CD51: =CO51+CZ51 -> 30817 | CE51: =SUM(BX51:CD51) -> 141066 | CF51: =CQ51+DB51 -> 126696 | CH51: 45689 | CI51: 3514 | CJ51: 7749 | CK51: 13440 | CL51: 13140 | CM51: 9184 | CN51: 9374 | CO51: 15950 | CP51: =SUM(CI51:CO51) -> 72351 | CQ51: ='Historic Data'!CZ48 -> 62062 | CS51: 45689 | CT51: 3678 | CU51: 7057 | CV51: 12753 | CW51: 11743 | CX51: 9242 | CY51: 9375 | CZ51: 14867 | DA51: =SUM(CT51:CZ51) -> 68715 | DB51: ='Historic Data'!DL48 -> 64634 | DD51: 45689 | DE51: 23360 | DF51: 37809 | DG51: 69236 | DH51: 64812 | DI51: 55459 | DJ51: 49084 | DK51: 90328 | DL51: =SUM(DE51:DK51) -> 390088 | DM51: ='Historic Data'!DX48 -> 399692 | DO51: 45689 | DY51: 45689 | EI51: 45689 | ES51: 45689 | FC51: 45689
B52: 45717 | C52: 418 | D52: 572 | E52: 1711 | F52: 911 | G52: 1115 | H52: 835 | I52: 1253 | J52: 6837 | L52: 45717 | M52: 418 | N52: 572 | O52: 1711 | P52: 911 | Q52: 1115 | R52: 835 | S52: 1253 | T52: 6837 | V52: 45717 | W52: 156466 | X52: 263882 | Y52: 504709 | Z52: 473159 | AA52: 408841 | AB52: 380634 | AC52: 586302 | AD52: 2872891 | AF52: 45717 | AG52: 118466 | AH52: 194128 | AI52: 376601 | AJ52: 345259 | AK52: 320200 | AL52: 283995 | AM52: 434590 | AN52: 2133990 | AP52: 45717 | AZ52: 45717 | BA52: =BC52+BM52 -> 183477 | BC52: 117859 | BD52: 168555 | BE52: 413971 | BF52: 230798 | BG52: 226826 | BH52: 301499 | BI52: 308827 | BJ52: =SUM(BC52:BI52) -> 1768335 | BK52: ='Historic Data'!BM49 -> 1768416 | BM52: 65618 | BN52: 132856 | BO52: 253466 | BP52: 151108 | BQ52: 145803 | BR52: 151728 | BS52: 212761 | BT52: =SUM(BM52:BS52) -> 1113340 | BU52: ='Historic Data'!BO49 -> 1113315 | BW52: 45717 | BX52: =CI52+CT52 -> 8992 | BY52: =CJ52+CU52 -> 19396 | BZ52: =CK52+CV52 -> 36937 | CA52: =CL52+CW52 -> 33573 | CB52: =CM52+CX52 -> 24211 | CC52: =CN52+CY52 -> 24508 | CD52: =CO52+CZ52 -> 42236 | CE52: =SUM(BX52:CD52) -> 189853 | CF52: =CQ52+DB52 -> 177219 | CH52: 45717 | CI52: 4053 | CJ52: 9769 | CK52: 18464 | CL52: 16828 | CM52: 11165 | CN52: 11743 | CO52: 21007 | CP52: =SUM(CI52:CO52) -> 93029 | CQ52: ='Historic Data'!CZ49 -> 80095 | CS52: 45717 | CT52: 4939 | CU52: 9627 | CV52: 18473 | CW52: 16745 | CX52: 13046 | CY52: 12765 | CZ52: 21229 | DA52: =SUM(CT52:CZ52) -> 96824 | DB52: ='Historic Data'!DL49 -> 97124 | DD52: 45717 | DE52: 31309 | DF52: 52304 | DG52: 99093 | DH52: 90339 | DI52: 78806 | DJ52: 70537 | DK52: 126692 | DL52: =SUM(DE52:DK52) -> 549080 | DM52: ='Historic Data'!DX49 -> 560782 | DO52: 45717 | DY52: 45717 | EI52: 45717 | ES52: 45717 | FC52: 45717
B53: 45748 | C53: 377 | D53: 470 | E53: 1331 | F53: 770 | G53: 896 | H53: 691 | I53: 1122 | J53: 5736 | L53: 45748 | M53: 377 | N53: 470 | O53: 1331 | P53: 770 | Q53: 896 | R53: 691 | S53: 1122 | T53: 5736 | V53: 45748 | W53: 162982 | X53: 269638 | Y53: 506724 | Z53: 484077 | AA53: 436113 | AB53: 407755 | AC53: 587950 | AD53: 2965512 | AF53: 45748 | AG53: 107203 | AH53: 174489 | AI53: 326631 | AJ53: 307910 | AK53: 300457 | AL53: 263781 | AM53: 388280 | AN53: 1932990 | AP53: 45748 | AZ53: 45748 | BA53: =BC53+BM53 -> 176769 | BC53: 111465 | BD53: 159846 | BE53: 406685 | BF53: 234525 | BG53: 212462 | BH53: 286179 | BI53: 267027 | BJ53: =SUM(BC53:BI53) -> 1678189 | BK53: ='Historic Data'!BM50 -> 1679030 | BM53: 65304 | BN53: 116755 | BO53: 255994 | BP53: 142351 | BQ53: 143680 | BR53: 155228 | BS53: 191710 | BT53: =SUM(BM53:BS53) -> 1071022 | BU53: ='Historic Data'!BO50 -> 1071469 | BW53: 45748 | BX53: =CI53+CT53 -> 7347 | BY53: =CJ53+CU53 -> 16731 | BZ53: =CK53+CV53 -> 30364 | CA53: =CL53+CW53 -> 28886 | CB53: =CM53+CX53 -> 20429 | CC53: =CN53+CY53 -> 22261 | CD53: =CO53+CZ53 -> 34976 | CE53: =SUM(BX53:CD53) -> 160994 | CF53: =CQ53+DB53 -> 151750 | CH53: 45748 | CI53: 3548 | CJ53: 9047 | CK53: 16026 | CL53: 15400 | CM53: 10089 | CN53: 11805 | CO53: 18119 | CP53: =SUM(CI53:CO53) -> 84034 | CQ53: ='Historic Data'!CZ50 -> 67847 | CS53: 45748 | CT53: 3799 | CU53: 7684 | CV53: 14338 | CW53: 13486 | CX53: 10340 | CY53: 10456 | CZ53: 16857 | DA53: =SUM(CT53:CZ53) -> 76960 | DB53: ='Historic Data'!DL50 -> 83903 | DD53: 45748 | DE53: 26297 | DF53: 45060 | DG53: 82023 | DH53: 77386 | DI53: 67093 | DJ53: 63150 | DK53: 109825 | DL53: =SUM(DE53:DK53) -> 470834 | DM53: ='Historic Data'!DX50 -> 485874 | DO53: 45748 | DY53: 45748 | EI53: 45748 | ES53: 45748 | FC53: 45748
...

Sheet Region 2025 Data
B2: T3 Sales Visits
C3: Mountain Region | D3: Mid Atlantic Region | E3: South Region | F3: Central Region | G3: West Region | H3: South Central Region | I3: East Region | J3: Sum of Regions | K3: National
B4: Jan - Dec '25 | C4: 1382533 | D4: 2100926 | E4: 5302232 | F4: 2574418 | G4: 2473390 | H4: 3576439 | I4: 3338475 | J4: 20748413 | K4: 20758263
B5: 25 Sig Even Months | C5: 607242 | D5: 920836 | E5: 2361144 | F5: 1109115 | G5: 1071680 | H5: 1585955 | I5: 1418404 | J5: 9074376 | K5: 9082638
B6: 25 Non-Sig Even Months | C6: 775291 | D6: 1180090 | E6: 2941088 | F6: 1465303 | G6: 1401710 | H6: 1990484 | I6: 1920071 | J6: 11674037 | K6: 11675625
B7: Action to Sales Rates
B8: 25 Sig Even Months | C8: 0.0032178275 | D8: 0.0033426148 | E8: 0.0037765592 | F8: 0.0038066386 | G8: 0.0050593461 | H8: 0.0027541765 | I8: 0.0047870705 | J8: 0.0038478679 | K8: 0.0038443677
B9: 25 Non-Sig Even Months | C9: 0.0030646557 | D9: 0.0029328272 | E9: 0.0033358403 | F9: 0.0034088513 | G9: 0.0042191323 | H9: 0.0024159953 | I9: 0.0038441287 | J9: 0.0033550519 | K9: 0.0033545956
B10: % of total FY: | C10: 0.066633193 | D10: 0.10125719 | E10: 0.2555488 | F10: 0.12407783 | G10: 0.11920864 | H10: 0.17237169 | I10: 0.16090267 | J10: 1 | K10: 1
B12: T3 VDPs | C12: T3 VDPs
C13: Mountain Region | D13: Mid Atlantic Region | E13: South Region | F13: Central Region | G13: West Region | H13: South Central Region | I13: East Region | J13: Sum of Regions | K13: National
B14: Jan - Dec '25 | C14: 782879 | D14: 1502872 | E14: 3410524 | F14: 1670443 | G14: 1621384 | H14: 1960699 | I14: 2225417 | J14: 13174218 | K14: 13177283
B15: 25 Sig Even Months | C15: 339255 | D15: 653047 | E15: 1547497 | F15: 729763 | G15: 691721 | H15: 874382 | I15: 946814 | J15: 5782479 | K15: 5784968
B16: 25 Non-Sig Even Months | C16: 443624 | D16: 849825 | E16: 1863027 | F16: 940680 | G16: 929663 | H16: 1086317 | I16: 1278603 | J16: 7391739 | K16: 7392315
B17: Action to Sales Rates
B18: 25 Sig Even Months | C18: 0.0057596793 | D18: 0.0047132902 | E18: 0.0057622083 | F18: 0.0057854399 | G18: 0.0078384204 | H18: 0.0049955283 | I18: 0.0071714191 | J18: 0.0060384136 | K18: 0.0060358156
B19: 25 Non-Sig Even Months | C19: 0.005355887 | D19: 0.0040726032 | E19: 0.0052661609 | F19: 0.0053099885 | G19: 0.006361445 | H19: 0.0044268846 | I19: 0.0057727066 | J19: 0.0052987531 | K19: 0.0052983402
B20: % of total FY: | C20: 0.059425083 | D20: 0.11407675 | E20: 0.25887867 | F20: 0.12679637 | G20: 0.1230725 | H20: 0.14882849 | I20: 0.16892213 | J20: 1 | K20: 1
B22: 2026 HVAs |T1 to T3 Referrals
C23: Mountain Region | D23: Mid Atlantic Region | E23: South Region | F23: Central Region | G23: West Region | H23: South Central Region | I23: East Region | J23: Sum of Regions | K23: National
B24: Jan - Dec '25 | C24: 42281 | D24: 92549 | E24: 170076 | F24: 161651 | G24: 113588 | H24: 121094 | I24: 197822 | J24: 899061 | K24: 919897
B25: 25 Sig Even Months | C25: 14554 | D25: 30387 | E25: 57719 | F25: 51260 | G25: 37094 | H25: 39100 | I25: 63190 | J25: 293304 | K25: 299076
B26: 25 Non-Sig Even Months | C26: 27727 | D26: 62162 | E26: 112357 | F26: 110391 | G26: 76494 | H26: 81994 | I26: 134632 | J26: 605757 | K26: 620821
B27: Action - Sales Rates
B28: 25 Sig Even Months | C28: 0.11151573 | D28: 0.082041663 | E28: 0.12841525 | F28: 0.066562622 | G28: 0.12098992 | H28: 0.093964194 | I28: 0.088384238 | J28: 0.098249598 | K28: 0.096353435
B29: 25 Non-Sig Even Months | C29: 0.097630468 | D29: 0.065087996 | E29: 0.10071469 | F29: 0.052585809 | G29: 0.089523361 | H29: 0.067114667 | I29: 0.063773843 | J29: 0.074727985 | K29: 0.072914737
B30: % of total FY: | C30: 0.047027955 | D30: 0.10293962 | E30: 0.1891707 | F30: 0.17979981 | G30: 0.1263407 | H30: 0.13468941 | I30: 0.22003179 | J30: 1 | K30: 1
B32: 2026 HVAs |T1 VDP Visits
C33: Mountain Region | D33: Mid Atlantic Region | E33: South Region | F33: Central Region | G33: West Region | H33: South Central Region | I33: East Region | J33: Sum of Regions | K33: National
B34: Jan - Dec '25 | C34: 46913 | D34: 90064 | E34: 169826 | F34: 158478 | G34: 124581 | H34: 128477 | I34: 196425 | J34: 914764 | K34: 923377
B35: 25 Sig Even Months | C35: 17879 | D35: 32580 | E35: 63704 | F35: 56387 | G35: 45896 | H35: 46952 | I35: 70280 | J35: 333678 | K35: 336553
B36: 25 Non-Sig Even Months | C36: 29034 | D36: 57484 | E36: 106122 | F36: 102091 | G36: 78685 | H36: 81525 | I36: 126145 | J36: 581086 | K36: 586824
B37: Action - Sales Rates
B38: 25 Sig Even Months | C38: 0.090776889 | D38: 0.076519337 | E38: 0.11635062 | F38: 0.060510401 | G38: 0.097786299 | H38: 0.078250128 | I38: 0.079467843 | J38: 0.086361702 | K38: 0.085623958
B39: 25 Non-Sig Even Months | C39: 0.093235517 | D39: 0.070384803 | E39: 0.10663199 | F39: 0.056861036 | G39: 0.087030565 | H39: 0.067500767 | I39: 0.068064529 | J39: 0.077900689 | K39: 0.077138972
B40: % of total FY: | C40: 0.051284266 | D40: 0.098455995 | E40: 0.18565007 | F40: 0.17324468 | G40: 0.13618922 | H40: 0.14044825 | I40: 0.21472751 | J40: 1 | K40: 1
B42: 2026 MVAs | (total 5x actions)
C43: Mountain Region | D43: Mid Atlantic Region | E43: South Region | F43: Central Region | G43: West Region | H43: South Central Region | I43: East Region | J43: Sum of Regions | K43: National
B44: Jan - Dec '25 | C44: 359856 | D44: 584457 | E44: 1103246 | F44: 1032905 | G44: 879558 | H44: 844887 | I44: 1410224 | J44: 6215133 | K44: 6374314
B45: 25 Sig Even Months | C45: 139243 | D45: 220667 | E45: 430789 | F45: 385348 | G45: 332040 | H45: 323709 | I45: 511648 | J45: 2343444 | K45: 2395842
...

Sheet Goal Methodology
B2: Metric | E2: Methodology
B3: Consideration | C3: Secondary | D3: T1 Visits | E3: Apply the ’25 sig / non-sig event month MVA-to-Visit ratio to ’26 monthly MVA goals.
D4: G.com VLP Vol | E4: Apply the ’25 sig / non-sig event month MVA-to-VLP ratio to ’26 monthly MVA goals.
B5: Research | C5: Primary | D5: Qualified Research Volume | E5: Calculate the total by summing T1 MVA goals and Endemic VDP goals (Endemic VDPs = sum across models). Weight the total using ’25 sales correlation (75% T1 MVAs / 25% Endemic VDPs).
D6: T1 MVAs | E6: Apply the ’25 sig / non-sig event month T1 MVA-to-Sales ratio to ’26 monthly Sales goals.
D7: Endemic VDPs | E7: Apply the ’25 sig / non-sig event month Endemic VDP-to-Sales ratio to ’26 monthly Sales goals.
C8: Secondary | D8: INM T1 MVAs | E8: Apply the ’25 sig / non-sig event month INM T1 MVA contribution to ’26 monthly T1 MVA goals.
B9: Shop | C9: Primary | D9: Qualified Shopping Volume | E9: Calculate the total by summing T3 Referral, T1 VDP (sum across models), and T3 Sales Visit goals. Weight each component using its respective ’25 Sales correlation.
D10: T1 to T3 Referral | E10: Apply the ’25 sig / non-sig event month T3 Referral-to-Sales ratio to ’26 monthly Sales goals.
D11: T1/T3 VDPs (T3 VDPs model level only) | E11: Apply the ’25 sig / non-sig event month VDP-to-Sales ratio to ’26 monthly Sales goals. Note: T3 Metrics include July '25 (whereas T1 does not)
D12: T3 Sales Visits (total level only) | E12: Apply the ’25 sig / non-sig event month T3 Sales Visit-to-Sales ratio to ’26 monthly Sales goals. Note: T3 Metrics include July '25 (whereas T1 does not)
C13: Monitoring | D13: T1 Unique Leads | E13: Apply ’25 sig / non-sig event month close rates and Lead-to-Sales contribution to ’26 monthly Sales goals.
B15: Notes | C15: Region Breakouts | E15: Regional and region–model goals reflect 2025 national conversion performance and 2026 sales allocation and model mix. They do not incorporate historical conversion rate differences at the regional or region–model level.

Sheet Region OP Sales Goals
B2: BRAND | C2: Model | D2: Jan | E2: Feb | F2: Mar | G2: Apr | H2: May | I2: Jun | J2: Jul | K2: Aug | L2: Sep | M2: Oct | N2: Nov | O2: Dec | P2: TOTAL | R2: Region Carflow 2+10 Final
C3: G70
C4: G80 | AH4: <-- BP
C5: GV90
C6: G90
C7: GV60
C8: GV70
C9: GV70 EV
C10: GV80 Coupe
C11: GV80
C12: TOTAL
C15: Region | D15: Jan | E15: Feb | F15: Mar | G15: Apr | H15: May | I15: Jun | J15: Jul | K15: Aug | L15: Sep | M15: Oct | N15: Nov | O15: Dec | P15: TOTAL | R15: Region | S15: Jan | T15: Feb | U15: Mar | V15: Apr | W15: May | X15: Jun | Y15: Jul | Z15: Aug | AA15: Sep | AB15: Oct | AC15: Nov | AD15: Dec | AE15: TOTAL
C16: CE | D16: 585 | E16: 704 | F16: 865 | G16: 542 | H16: 733 | I16: 784 | J16: 706 | K16: 732 | L16: 853 | M16: 848 | N16: 833 | O16: 803 | P16: 9009 | R16: CE | S16: =D16/D23 -> 0.12074303 | T16: =E16/E23 -> 0.1348659 | U16: =F16/F23 -> 0.13348765 | V16: =G16/G23 -> 0.089809445 | W16: =H16/H23 -> 0.10811209 | X16: =I16/I23 -> 0.11597633 | Y16: =J16/J23 -> 0.11996602 | Z16: =K16/K23 -> 0.11970564 | ... AE16: =P16/P23 -> 0.11742548
C17: EA | D17: 935 | E17: 1015 | F17: 1284 | G17: 1306 | H17: 1218 | I17: 1212 | J17: 1088 | K17: 1127 | L17: 1341 | M17: 1311 | N17: 1290 | O17: 1260 | P17: 14926 | R17: EA | S17: =D17/D23 -> 0.19298246 | T17: =E17/E23 -> 0.19444444 | U17: =F17/F23 -> 0.19814815 | V17: =G17/G23 -> 0.21640431 | W17: =H17/H23 -> 0.17964602 | X17: =I17/I23 -> 0.17928994 | Y17: =J17/J23 -> 0.18487681 | Z17: =K17/K23 -> 0.1843009 | ... AE17: =P17/P23 -> 0.19454908
C18: MA | D18: 415 | E18: 470 | F18: 570 | G18: 484 | H18: 537 | I18: 536 | J18: 487 | K18: 511 | L18: 599 | M18: 603 | N18: 587 | O18: 578 | P18: 6440 | R18: MA | S18: =D18/D23 -> 0.085655315 | T18: =E18/E23 -> 0.090038314 | U18: =F18/F23 -> 0.087962963 | V18: =G18/G23 -> 0.08019884 | W18: =H18/H23 -> 0.07920354 | X18: =I18/I23 -> 0.079289941 | Y18: =J18/J23 -> 0.082752761 | Z18: =K18/K23 -> 0.083565004 | ... AE18: =P18/P23 -> 0.083940512
C19: MS | D19: 255 | E19: 290 | F19: 355 | G19: 294 | H19: 349 | I19: 397 | J19: 355 | K19: 376 | L19: 415 | M19: 411 | N19: 394 | O19: 382 | P19: 4398 | R19: MS | S19: =D19/D23 -> 0.052631579 | T19: =E19/E23 -> 0.055555556 | U19: =F19/F23 -> 0.054783951 | V19: =G19/G23 -> 0.048715824 | W19: =H19/H23 -> 0.051474926 | X19: =I19/I23 -> 0.058727811 | Y19: =J19/J23 -> 0.060322855 | Z19: =K19/K23 -> 0.061488144 | ... AE19: =P19/P23 -> 0.057324592
C20: SC | D20: 630 | E20: 675 | F20: 825 | G20: 695 | H20: 885 | I20: 848 | J20: 726 | K20: 754 | L20: 867 | M20: 854 | N20: 839 | O20: 818 | P20: 9473 | R20: SC | S20: =D20/D23 -> 0.13003096 | T20: =E20/E23 -> 0.12931034 | U20: =F20/F23 -> 0.12731481 | V20: =G20/G23 -> 0.11516156 | W20: =H20/H23 -> 0.13053097 | X20: =I20/I23 -> 0.12544379 | Y20: =J20/J23 -> 0.12336449 | Z20: =K20/K23 -> 0.12330335 | ... AE20: =P20/P23 -> 0.12347336
C21: SO | D21: 1310 | E21: 1251 | F21: 1621 | G21: 1629 | H21: 1875 | I21: 1835 | J21: 1543 | K21: 1606 | L21: 1804 | M21: 1754 | N21: 1724 | O21: 1695 | P21: 19786 | R21: SO | S21: =D21/D23 -> 0.27038184 | T21: =E21/E23 -> 0.23965517 | U21: =F21/F23 -> 0.25015432 | V21: =G21/G23 -> 0.26992543 | W21: =H21/H23 -> 0.27654867 | X21: =I21/I23 -> 0.2714497 | Y21: =J21/J23 -> 0.26219201 | Z21: =K21/K23 -> 0.26263287 | ... AE21: =P21/P23 -> 0.25789549
C22: WE | D22: 715 | E22: 815 | F22: 960 | G22: 1085 | H22: 1183 | I22: 1148 | J22: 980 | K22: 1009 | L22: 1106 | M22: 1059 | N22: 1058 | O22: 1029 | P22: 12541 | R22: WE | S22: =D22/D23 -> 0.14757482 | T22: =E22/E23 -> 0.15613027 | U22: =F22/F23 -> 0.14814815 | V22: =G22/G23 -> 0.17978459 | W22: =H22/H23 -> 0.17448378 | X22: =I22/I23 -> 0.16982249 | Y22: =J22/J23 -> 0.16652506 | Z22: =K22/K23 -> 0.16500409 | ... AE22: =P22/P23 -> 0.16346242
C23: TOTAL | D23: 4845 | E23: 5220 | F23: 6480 | G23: 6035 | H23: 6780 | I23: 6760 | J23: 5885 | K23: 6115 | L23: 6985 | M23: 6840 | N23: 6725 | O23: 6565 | P23: 76721 | R23: TOTAL | S23: =D23/D23 -> 1 | T23: =E23/E23 -> 1 | U23: =F23/F23 -> 1 | V23: =G23/G23 -> 1 | W23: =H23/H23 -> 1 | X23: =I23/I23 -> 1 | Y23: =J23/J23 -> 1 | Z23: =K23/K23 -> 1 | ... AE23: =P23/P23 -> 1
B26: G70 | C26: Region | D26: Jan | E26: Feb | F26: Mar | G26: Apr | H26: May | I26: Jun | J26: Jul | K26: Aug | L26: Sep | M26: Oct | N26: Nov | O26: Dec | P26: TOTAL | R26: Region | S26: Jan | T26: Feb | U26: Mar | V26: Apr | W26: May | X26: Jun | Y26: Jul | Z26: Aug | AA26: Sep | AB26: Oct | AC26: Nov | AD26: Dec | AE26: TOTAL
